<?xml version="1.0"?>
<sdf version="1.7">
    <!-- Kinova robot j2s7s300 -->
    <!-- j - Jaco -->
    <!-- 2 - v2 (Gen2) -->
    <!-- s - spherical wrist -->
    <!-- 7 - 7 DOF -->
    <!-- s - service -->
    <!-- 3 - 3 finger gripper -->
    <!-- 0 - reserved -->
    <!-- 0 - reserved -->
    <model name="j2s7s300">

        <!-- Fix To World -->
        <joint name="j2s7s300_joint_world" type="fixed">
            <parent>world</parent>
            <child>j2s7s300_link_base</child>
        </joint>

        <!-- Arm Links -->
        <link name="j2s7s300_link_base">
            <visual name="j2s7s300_link_base_visual">
                <geometry>
                    <mesh>
                        <uri>meshes/visual/base.dae</uri>
                    </mesh>
                </geometry>
            </visual>
            <collision name="j2s7s300_link_base_collision">
                <geometry>
                    <mesh>
                        <uri>meshes/collision/base.stl</uri>
                    </mesh>
                </geometry>
                <surface>
                    <friction>
                        <ode>
                            <mu>0.75</mu>
                            <mu2>0.75</mu2>
                        </ode>
                    </friction>
                </surface>
            </collision>
            <inertial>
                <pose>0 0 0.1255 0 0 0</pose>
                <mass>0.46784</mass>
                <inertia>
                    <ixx>0.000951270861568</ixx>
                    <iyy>0.000951270861568</iyy>
                    <izz>0.000374272</izz>
                    <ixy>0</ixy>
                    <ixz>0</ixz>
                    <iyz>0</iyz>
                </inertia>
            </inertial>
        </link>

        <link name="j2s7s300_link_1">
            <pose relative_to="j2s7s300_joint_1">0 0 0 0 0 0</pose>
            <visual name="j2s7s300_link_1_visual">
                <geometry>
                    <mesh>
                        <uri>meshes/visual/shoulder.dae</uri>
                    </mesh>
                </geometry>
            </visual>
            <visual name="j2s7s300_link_1_visual_1">
                <geometry>
                    <mesh>
                        <uri>meshes/visual/ring_big.dae</uri>
                    </mesh>
                </geometry>
            </visual>
            <collision name="j2s7s300_link_1_collision">
                <geometry>
                    <mesh>
                        <uri>meshes/collision/shoulder.stl</uri>
                    </mesh>
                </geometry>
                <surface>
                    <friction>
                        <ode>
                            <mu>0.75</mu>
                            <mu2>0.75</mu2>
                        </ode>
                    </friction>
                </surface>
            </collision>
            <inertial>
                <pose>0 -0.002 -0.0605 0 0 0</pose>
                <mass>0.7477</mass>
                <inertia>
                    <ixx>0.00152031725204</ixx>
                    <iyy>0.00152031725204</iyy>
                    <izz>0.00059816</izz>
                    <ixy>0</ixy>
                    <ixz>0</ixz>
                    <iyz>0</iyz>
                </inertia>
            </inertial>
        </link>

        <link name="j2s7s300_link_2">
            <pose relative_to="j2s7s300_joint_2">0 0 0 0 0 0</pose>
            <visual name="j2s7s300_link_2_visual">
                <geometry>
                    <mesh>
                        <uri>meshes/visual/arm_half_1.dae</uri>
                    </mesh>
                </geometry>
            </visual>
            <visual name="j2s7s300_link_2_visual_1">
                <geometry>
                    <mesh>
                        <uri>meshes/visual/ring_big.dae</uri>
                    </mesh>
                </geometry>
            </visual>
            <collision name="j2s7s300_link_2_collision">
                <geometry>
                    <mesh>
                        <uri>meshes/collision/arm_half_1.stl</uri>
                    </mesh>
                </geometry>
                <surface>
                    <friction>
                        <ode>
                            <mu>0.75</mu>
                            <mu2>0.75</mu2>
                        </ode>
                    </friction>
                </surface>
            </collision>
            <inertial>
                <pose>0 -0.103563213 0 0 0 0</pose>
                <mass>0.8447</mass>
                <inertia>
                    <ixx>0.00247073761701</ixx>
                    <iyy>0.000380115</iyy>
                    <izz>0.00247073761701</izz>
                    <ixy>0</ixy>
                    <ixz>0</ixz>
                    <iyz>0</iyz>
                </inertia>
            </inertial>
        </link>

        <link name="j2s7s300_link_3">
            <pose relative_to="j2s7s300_joint_3">0 0 0 0 0 0</pose>
            <visual name="j2s7s300_link_3_visual">
                <geometry>
                    <mesh>
                        <uri>meshes/visual/arm_half_2.dae</uri>
                    </mesh>
                </geometry>
            </visual>
            <visual name="j2s7s300_link_3_visual_1">
                <geometry>
                    <mesh>
                        <uri>meshes/visual/ring_big.dae</uri>
                    </mesh>
                </geometry>
            </visual>
            <collision name="j2s7s300_link_3_collision">
                <geometry>
                    <mesh>
                        <uri>meshes/collision/arm_half_2.stl</uri>
                    </mesh>
                </geometry>
                <surface>
                    <friction>
                        <ode>
                            <mu>0.75</mu>
                            <mu2>0.75</mu2>
                        </ode>
                    </friction>
                </surface>
            </collision>
            <inertial>
                <pose>0 0 -0.1022447445 0 0 0</pose>
                <mass>0.8447</mass>
                <inertia>
                    <ixx>0.00247073761701</ixx>
                    <iyy>0.00247073761701</iyy>
                    <izz>0.000380115</izz>
                    <ixy>0</ixy>
                    <ixz>0</ixz>
                    <iyz>0</iyz>
                </inertia>
            </inertial>
        </link>

        <link name="j2s7s300_link_4">
            <pose relative_to="j2s7s300_joint_4">0 0 0 0 0 0</pose>
            <visual name="j2s7s300_link_4_visual">
                <geometry>
                    <mesh>
                        <uri>meshes/visual/forearm.dae</uri>
                    </mesh>
                </geometry>
            </visual>
            <visual name="j2s7s300_link_4_visual_1">
                <geometry>
                    <mesh>
                        <uri>meshes/visual/ring_big.dae</uri>
                    </mesh>
                </geometry>
            </visual>
            <collision name="j2s7s300_link_4_collision">
                <geometry>
                    <mesh>
                        <uri>meshes/collision/forearm.stl</uri>
                    </mesh>
                </geometry>
                <surface>
                    <friction>
                        <ode>
                            <mu>0.75</mu>
                            <mu2>0.75</mu2>
                        </ode>
                    </friction>
                </surface>
            </collision>
            <inertial>
                <pose>0 0.081 -0.0086 0 0 0</pose>
                <mass>0.6763</mass>
                <inertia>
                    <ixx>0.00142022431908</ixx>
                    <iyy>0.000304335</iyy>
                    <izz>0.00142022431908</izz>
                    <ixy>0</ixy>
                    <ixz>0</ixz>
                    <iyz>0</iyz>
                </inertia>
            </inertial>
        </link>

        <link name="j2s7s300_link_5">
            <pose relative_to="j2s7s300_joint_5">0 0 0 0 0 0</pose>
            <visual name="j2s7s300_link_5_visual">
                <geometry>
                    <mesh>
                        <uri>meshes/visual/wrist_spherical_1.dae</uri>
                    </mesh>
                </geometry>
            </visual>
            <visual name="j2s7s300_link_5_visual_1">
                <geometry>
                    <mesh>
                        <uri>meshes/visual/ring_small.dae</uri>
                    </mesh>
                </geometry>
            </visual>
            <collision name="j2s7s300_link_5_collision">
                <geometry>
                    <mesh>
                        <uri>meshes/collision/wrist_spherical_1.stl</uri>
                    </mesh>
                </geometry>
                <surface>
                    <friction>
                        <ode>
                            <mu>0.75</mu>
                            <mu2>0.75</mu2>
                        </ode>
                    </friction>
                </surface>
            </collision>
            <inertial>
                <pose>0 0.0028848942 -0.0541932613 0 0 0</pose>
                <mass>0.463</mass>
                <inertia>
                    <ixx>0.0004321316048</ixx>
                    <iyy>0.0004321316048</iyy>
                    <izz>9.26e-05</izz>
                    <ixy>0</ixy>
                    <ixz>0</ixz>
                    <iyz>0</iyz>
                </inertia>
            </inertial>
        </link>

        <link name="j2s7s300_link_6">
            <pose relative_to="j2s7s300_joint_6">0 0 0 0 0 0</pose>
            <visual name="j2s7s300_link_6_visual">
                <geometry>
                    <mesh>
                        <uri>meshes/visual/wrist_spherical_2.dae</uri>
                    </mesh>
                </geometry>
            </visual>
            <visual name="j2s7s300_link_6_visual_1">
                <geometry>
                    <mesh>
                        <uri>meshes/visual/ring_small.dae</uri>
                    </mesh>
                </geometry>
            </visual>
            <collision name="j2s7s300_link_6_collision">
                <geometry>
                    <mesh>
                        <uri>meshes/collision/wrist_spherical_2.stl</uri>
                    </mesh>
                </geometry>
                <surface>
                    <friction>
                        <ode>
                            <mu>0.75</mu>
                            <mu2>0.75</mu2>
                        </ode>
                    </friction>
                </surface>
            </collision>
            <inertial>
                <pose>0 0.0497208855 -0.0028562765 0 0 0</pose>
                <mass>0.463</mass>
                <inertia>
                    <ixx>0.0004321316048</ixx>
                    <iyy>9.26e-05</iyy>
                    <izz>0.0004321316048</izz>
                    <ixy>0</ixy>
                    <ixz>0</ixz>
                    <iyz>0</iyz>
                </inertia>
            </inertial>
        </link>

        <link name="j2s7s300_link_7">
            <pose relative_to="j2s7s300_joint_7">0 0 0 0 0 0</pose>
            <visual name="j2s7s300_link_7_visual">
                <geometry>
                    <mesh>
                        <uri>meshes/visual/hand_3finger.dae</uri>
                    </mesh>
                </geometry>
            </visual>
            <visual name="j2s7s300_link_7_visual_1">
                <geometry>
                    <mesh>
                        <uri>meshes/visual/ring_small.dae</uri>
                    </mesh>
                </geometry>
            </visual>
            <collision name="j2s7s300_link_7_collision">
                <geometry>
                    <mesh>
                        <uri>meshes/collision/hand_3finger.stl</uri>
                    </mesh>
                </geometry>
                <surface>
                    <friction>
                        <ode>
                            <mu>0.75</mu>
                            <mu2>0.75</mu2>
                        </ode>
                    </friction>
                </surface>
            </collision>
            <inertial>
                <pose>0 0 -0.06 0 0 0</pose>
                <mass>0.99</mass>
                <inertia>
                    <ixx>0.0003453236187</ixx>
                    <iyy>0.0003453236187</iyy>
                    <izz>0.0005816</izz>
                    <ixy>0</ixy>
                    <ixz>0</ixz>
                    <iyz>0</iyz>
                </inertia>
            </inertial>
        </link>


        <!-- Arm Joints -->
        <joint name="j2s7s300_joint_1" type="revolute">
            <pose relative_to="j2s7s300_link_base">0 0 0.15675 0 3.14159265359 0</pose>
            <parent>j2s7s300_link_base</parent>
            <child>j2s7s300_link_1</child>
            <axis>
                <xyz>0 0 1</xyz>
                <limit>
                    <effort>30.5</effort>
                    <lower>-31.415927</lower>
                    <upper>31.415927</upper>
                    <velocity>1</velocity>
                </limit>
                <dynamics>
                    <spring_reference>0</spring_reference>
                    <spring_stiffness>0</spring_stiffness>
                    <damping>16.0</damping>
                    <friction>0.6</friction>
                </dynamics>
            </axis>
        </joint>

        <joint name="j2s7s300_joint_2" type="revolute">
            <pose relative_to="j2s7s300_link_1">0 0.0016 -0.11875 -1.57079632679 -0 -3.141592653589587</pose>
            <parent>j2s7s300_link_1</parent>
            <child>j2s7s300_link_2</child>
            <axis>
                <xyz>0 0 1</xyz>
                <limit>
                    <effort>30.5</effort>
                    <lower>0.820304748437</lower>
                    <upper>5.46288055874</upper>
                    <velocity>1</velocity>
                </limit>
                <dynamics>
                    <spring_reference>0</spring_reference>
                    <spring_stiffness>0</spring_stiffness>
                    <damping>8.5</damping>
                    <friction>0.9</friction>
                </dynamics>
            </axis>
        </joint>

        <joint name="j2s7s300_joint_3" type="revolute">
            <pose relative_to="j2s7s300_link_2">0 -0.205 0 -1.57079632679 0 0</pose>
            <parent>j2s7s300_link_2</parent>
            <child>j2s7s300_link_3</child>
            <axis>
                <xyz>0 0 1</xyz>
                <limit>
                    <effort>30.5</effort>
                    <lower>-31.415927</lower>
                    <upper>31.415927</upper>
                    <velocity>1</velocity>
                </limit>
                <dynamics>
                    <spring_reference>0</spring_reference>
                    <spring_stiffness>0</spring_stiffness>
                    <damping>7.5</damping>
                    <friction>0.75</friction>
                </dynamics>
            </axis>
        </joint>

        <joint name="j2s7s300_joint_4" type="revolute">
            <pose relative_to="j2s7s300_link_3">0 0 -0.205 1.57079632679 0 -3.141592653589587</pose>
            <parent>j2s7s300_link_3</parent>
            <child>j2s7s300_link_4</child>
            <axis>
                <xyz>0 0 1</xyz>
                <limit>
                    <effort>30.5</effort>
                    <lower>0.5235987755980001</lower>
                    <upper>5.75958653158</upper>
                    <velocity>1</velocity>
                </limit>
                <dynamics>
                    <spring_reference>0</spring_reference>
                    <spring_stiffness>0</spring_stiffness>
                    <damping>6.5</damping>
                    <friction>0.95</friction>
                </dynamics>
            </axis>
        </joint>

        <joint name="j2s7s300_joint_5" type="revolute">
            <pose relative_to="j2s7s300_link_4">0 0.2073 -0.0114 -1.57079632679 0 -3.141592653589587</pose>
            <parent>j2s7s300_link_4</parent>
            <child>j2s7s300_link_5</child>
            <axis>
                <xyz>0 0 1</xyz>
                <limit>
                    <effort>13.6</effort>
                    <lower>-31.415927</lower>
                    <upper>31.415927</upper>
                    <velocity>1</velocity>
                </limit>
                <dynamics>
                    <spring_reference>0</spring_reference>
                    <spring_stiffness>0</spring_stiffness>
                    <damping>4.5</damping>
                    <friction>0.35</friction>
                </dynamics>
            </axis>
        </joint>

        <joint name="j2s7s300_joint_6" type="revolute">
            <pose relative_to="j2s7s300_link_5">0 0 -0.10375 1.57079632679 0 -3.141592653589587</pose>
            <parent>j2s7s300_link_5</parent>
            <child>j2s7s300_link_6</child>
            <axis>
                <xyz>0 0 1</xyz>
                <limit>
                    <effort>13.6</effort>
                    <lower>1.1344640138</lower>
                    <upper>5.14872129338</upper>
                    <velocity>1</velocity>
                </limit>
                <dynamics>
                    <spring_reference>0</spring_reference>
                    <spring_stiffness>0</spring_stiffness>
                    <damping>4.0</damping>
                    <friction>0.3</friction>
                </dynamics>
            </axis>
        </joint>

        <joint name="j2s7s300_joint_7" type="revolute">
            <pose relative_to="j2s7s300_link_6">0 0.10375 0 -1.57079632679 -0 -3.141592653589587</pose>
            <parent>j2s7s300_link_6</parent>
            <child>j2s7s300_link_7</child>
            <axis>
                <xyz>0 0 1</xyz>
                <limit>
                    <effort>13.6</effort>
                    <lower>-31.415927</lower>
                    <upper>31.415927</upper>
                    <velocity>1</velocity>
                </limit>
                <dynamics>
                    <spring_reference>0</spring_reference>
                    <spring_stiffness>0</spring_stiffness>
                    <damping>3.5</damping>
                    <friction>0.2</friction>
                </dynamics>
            </axis>
        </joint>


        <!-- Hand Links -->
        <link name="j2s7s300_link_finger_1">
            <pose relative_to="j2s7s300_joint_finger_1">0 0 0 0 0 0</pose>
            <visual name="j2s7s300_link_finger_1_visual">
                <geometry>
                    <mesh>
                        <uri>meshes/visual/finger_proximal.dae</uri>
                    </mesh>
                </geometry>
            </visual>
            <visual name="j2s7s300_link_finger_1_fixed_joint_lump__j2s7s300_link_finger_tip_1_visual_1">
                <pose>0.044 -0.003 0 0 0 0</pose>
                <geometry>
                    <mesh>
                        <uri>meshes/visual/finger_distal.dae</uri>
                    </mesh>
                </geometry>
            </visual>
            <collision name="j2s7s300_link_finger_1_collision">
                <geometry>
                    <mesh>
                        <uri>meshes/collision/finger_proximal.stl</uri>
                    </mesh>
                </geometry>
                <surface>
                    <friction>
                        <ode>
                            <mu>2.15</mu>
                            <mu2>2.15</mu2>
                        </ode>
                    </friction>
                </surface>
            </collision>
            <collision name="j2s7s300_link_finger_1_fixed_joint_lump__j2s7s300_link_finger_tip_1_collision_1">
                <pose>0.044 -0.003 0 0 0 0</pose>
                <geometry>
                    <mesh>
                        <uri>meshes/collision/finger_distal.stl</uri>
                    </mesh>
                </geometry>
                <surface>
                    <friction>
                        <ode>
                            <mu>2.15</mu>
                            <mu2>2.15</mu2>
                        </ode>
                    </friction>
                </surface>
            </collision>
            <inertial>
                <pose>0.044 -0.0015 0 0 0 0</pose>
                <mass>0.02</mass>
                <inertia>
                    <ixx>1.62499368e-06</ixx>
                    <iyy>1.125999368000001e-05</iyy>
                    <izz>9.885000000000011e-06</izz>
                    <ixy>6.600000000000002e-07</ixy>
                    <ixz>0</ixz>
                    <iyz>0</iyz>
                </inertia>
            </inertial>
        </link>

        <link name="j2s7s300_link_finger_2">
            <pose relative_to="j2s7s300_joint_finger_2">0 0 0 0 0 0</pose>
            <visual name="j2s7s300_link_finger_2_visual">
                <geometry>
                    <mesh>
                        <uri>meshes/visual/finger_proximal.dae</uri>
                    </mesh>
                </geometry>
            </visual>
            <visual name="j2s7s300_link_finger_2_fixed_joint_lump__j2s7s300_link_finger_tip_2_visual_1">
                <pose>0.044 -0.003 0 0 0 0</pose>
                <geometry>
                    <mesh>
                        <uri>meshes/visual/finger_distal.dae</uri>
                    </mesh>
                </geometry>
            </visual>
            <collision name="j2s7s300_link_finger_2_collision">
                <geometry>
                    <mesh>
                        <uri>meshes/collision/finger_proximal.stl</uri>
                    </mesh>
                </geometry>
                <surface>
                    <friction>
                        <ode>
                            <mu>2.15</mu>
                            <mu2>2.15</mu2>
                        </ode>
                    </friction>
                </surface>
            </collision>
            <collision name="j2s7s300_link_finger_2_fixed_joint_lump__j2s7s300_link_finger_tip_2_collision_1">
                <pose>0.044 -0.003 0 0 0 0</pose>
                <geometry>
                    <mesh>
                        <uri>meshes/collision/finger_distal.stl</uri>
                    </mesh>
                </geometry>
                <surface>
                    <friction>
                        <ode>
                            <mu>2.15</mu>
                            <mu2>2.15</mu2>
                        </ode>
                    </friction>
                </surface>
            </collision>
            <inertial>
                <pose>0.044 -0.0015 0 0 0 0</pose>
                <mass>0.02</mass>
                <inertia>
                    <ixx>1.62499368e-06</ixx>
                    <iyy>1.125999368000001e-05</iyy>
                    <izz>9.885000000000011e-06</izz>
                    <ixy>6.600000000000002e-07</ixy>
                    <ixz>0</ixz>
                    <iyz>0</iyz>
                </inertia>
            </inertial>
        </link>

        <link name="j2s7s300_link_finger_3">
            <pose relative_to="j2s7s300_joint_finger_3">0 0 0 0 0 0</pose>
            <visual name="j2s7s300_link_finger_3_visual">
                <geometry>
                    <mesh>
                        <uri>meshes/visual/finger_proximal.dae</uri>
                    </mesh>
                </geometry>
            </visual>
            <visual name="j2s7s300_link_finger_3_fixed_joint_lump__j2s7s300_link_finger_tip_3_visual_1">
                <pose>0.044 -0.003 0 0 0 0</pose>
                <geometry>
                    <mesh>
                        <uri>meshes/visual/finger_distal.dae</uri>
                    </mesh>
                </geometry>
            </visual>
            <collision name="j2s7s300_link_finger_3_collision">
                <geometry>
                    <mesh>
                        <uri>meshes/collision/finger_proximal.stl</uri>
                    </mesh>
                </geometry>
                <surface>
                    <friction>
                        <ode>
                            <mu>2.15</mu>
                            <mu2>2.15</mu2>
                        </ode>
                    </friction>
                </surface>
            </collision>
            <collision name="j2s7s300_link_finger_3_fixed_joint_lump__j2s7s300_link_finger_tip_3_collision_1">
                <pose>0.044 -0.003 0 0 0 0</pose>
                <geometry>
                    <mesh>
                        <uri>meshes/collision/finger_distal.stl</uri>
                    </mesh>
                </geometry>
                <surface>
                    <friction>
                        <ode>
                            <mu>2.15</mu>
                            <mu2>2.15</mu2>
                        </ode>
                    </friction>
                </surface>
            </collision>
            <inertial>
                <pose>0.044 -0.0015 0 0 0 0</pose>
                <mass>0.02</mass>
                <inertia>
                    <ixx>1.62499368e-06</ixx>
                    <iyy>1.125999368000001e-05</iyy>
                    <izz>9.885000000000011e-06</izz>
                    <ixy>6.600000000000002e-07</ixy>
                    <ixz>0</ixz>
                    <iyz>0</iyz>
                </inertia>
            </inertial>
        </link>


        <!-- Finger Joints -->
        <joint name="j2s7s300_joint_finger_1" type="revolute">
            <pose relative_to="j2s7s300_link_7">0.00279 0.03126 -0.11467 -1.570796327 0.6492624816635821 1.35961148639407</pose>
            <parent>j2s7s300_link_7</parent>
            <child>j2s7s300_link_finger_1</child>
            <axis>
                <xyz>0 0 1</xyz>
                <limit>
                    <effort>20</effort>
                    <lower>0</lower>
                    <upper>1.3</upper>
                    <velocity>1</velocity>
                </limit>
                <dynamics>
                    <spring_reference>0</spring_reference>
                    <spring_stiffness>0</spring_stiffness>
                    <damping>0.5</damping>
                    <friction>0.05</friction>
                </dynamics>
            </axis>
        </joint>

        <joint name="j2s7s300_joint_finger_2" type="revolute">
            <pose relative_to="j2s7s300_link_7">0.02226 -0.02707 -0.11482 -1.570796327 0.6492624816635825 -1.38614049188413</pose>
            <parent>j2s7s300_link_7</parent>
            <child>j2s7s300_link_finger_2</child>
            <axis>
                <xyz>0 0 1</xyz>
                <limit>
                    <effort>20</effort>
                    <lower>0</lower>
                    <upper>1.3</upper>
                    <velocity>1</velocity>
                </limit>
                <dynamics>
                    <spring_reference>0</spring_reference>
                    <spring_stiffness>0</spring_stiffness>
                    <damping>0.5</damping>
                    <friction>0.05</friction>
                </dynamics>
            </axis>
        </joint>

        <joint name="j2s7s300_joint_finger_3" type="revolute">
            <pose relative_to="j2s7s300_link_7">-0.02226 -0.02707 -0.11482 -1.570796327 0.6492624816635821 -1.75545216211587</pose>
            <parent>j2s7s300_link_7</parent>
            <child>j2s7s300_link_finger_3</child>
            <axis>
                <xyz>0 0 1</xyz>
                <limit>
                    <effort>20</effort>
                    <lower>0</lower>
                    <upper>1.3</upper>
                    <velocity>1</velocity>
                </limit>
                <dynamics>
                    <spring_reference>0</spring_reference>
                    <spring_stiffness>0</spring_stiffness>
                    <damping>0.5</damping>
                    <friction>0.05</friction>
                </dynamics>
            </axis>
        </joint>

        <!-- End-effector -->
        <link name="j2s7s300_end_effector">
            <pose relative_to="end_effector_frame_fixed_joint">0 0 0 0 0 0</pose>
        </link>
        <joint name="end_effector_frame_fixed_joint" type="fixed">
            <pose relative_to="j2s7s300_link_7">0 0 -0.16 3.14159265359 0 1.57079632679</pose>
            <parent>j2s7s300_link_7</parent>
            <child>j2s7s300_end_effector</child>
        </joint>

    </model>
</sdf>
