<?xml version="1.0"?>
<!-- Kinova robot j2s7s300 -->
<!-- j - Jaco -->
<!-- 2 - v2 (Gen2) -->
<!-- s - spherical wrist -->
<!-- 7 - 7 DOF -->
<!-- s - service -->
<!-- 3 - 3 finger gripper -->
<!-- 0 - reserved -->
<!-- 0 - reserved -->
<robot name="j2s7s300">

    <!-- Arm Links -->
    <link name="j2s7s300_link_base">
        <visual>
            <geometry>
                <mesh filename="package://kinova_j2s7s300_ign/meshes/visual/base.dae"/>
            </geometry>
        </visual>
        <collision>
            <geometry>
                <mesh filename="package://kinova_j2s7s300_ign/meshes/collision/base.stl"/>
            </geometry>
        </collision>
    </link>

    <link name="j2s7s300_link_1">
        <visual>
            <geometry>
                <mesh filename="package://kinova_j2s7s300_ign/meshes/visual/shoulder.dae"/>
            </geometry>
        </visual>
        <visual>
            <geometry>
                <mesh filename="package://kinova_j2s7s300_ign/meshes/visual/ring_big.dae"/>
            </geometry>
        </visual>
        <collision>
            <geometry>
                <mesh filename="package://kinova_j2s7s300_ign/meshes/collision/shoulder.stl"/>
            </geometry>
        </collision>
    </link>

    <link name="j2s7s300_link_2">
        <visual>
            <geometry>
                <mesh filename="package://kinova_j2s7s300_ign/meshes/visual/arm_half_1.dae"/>
            </geometry>
        </visual>
        <visual>
            <geometry>
                <mesh filename="package://kinova_j2s7s300_ign/meshes/visual/ring_big.dae"/>
            </geometry>
        </visual>
        <collision>
            <geometry>
                <mesh filename="package://kinova_j2s7s300_ign/meshes/collision/arm_half_1.stl"/>
            </geometry>
        </collision>
    </link>

    <link name="j2s7s300_link_3">
        <visual>
            <geometry>
                <mesh filename="package://kinova_j2s7s300_ign/meshes/visual/arm_half_2.dae"/>
            </geometry>
        </visual>
        <visual>
            <geometry>
                <mesh filename="package://kinova_j2s7s300_ign/meshes/visual/ring_big.dae"/>
            </geometry>
        </visual>
        <collision>
            <geometry>
                <mesh filename="package://kinova_j2s7s300_ign/meshes/collision/arm_half_2.stl"/>
            </geometry>
        </collision>
    </link>

    <link name="j2s7s300_link_4">
        <visual>
            <geometry>
                <mesh filename="package://kinova_j2s7s300_ign/meshes/visual/forearm.dae"/>
            </geometry>
        </visual>
        <visual>
            <geometry>
                <mesh filename="package://kinova_j2s7s300_ign/meshes/visual/ring_big.dae"/>
            </geometry>
        </visual>
        <collision>
            <geometry>
                <mesh filename="package://kinova_j2s7s300_ign/meshes/collision/forearm.stl"/>
            </geometry>
        </collision>
    </link>

    <link name="j2s7s300_link_5">
        <visual>
            <geometry>
                <mesh filename="package://kinova_j2s7s300_ign/meshes/visual/wrist_spherical_1.dae"/>
            </geometry>
        </visual>
        <visual>
            <geometry>
                <mesh filename="package://kinova_j2s7s300_ign/meshes/visual/ring_small.dae"/>
            </geometry>
        </visual>
        <collision>
            <geometry>
                <mesh filename="package://kinova_j2s7s300_ign/meshes/collision/wrist_spherical_1.stl"/>
            </geometry>
        </collision>
    </link>

    <link name="j2s7s300_link_6">
        <visual>
            <geometry>
                <mesh filename="package://kinova_j2s7s300_ign/meshes/visual/wrist_spherical_2.dae"/>
            </geometry>
        </visual>
        <visual>
            <geometry>
                <mesh filename="package://kinova_j2s7s300_ign/meshes/visual/ring_small.dae"/>
            </geometry>
        </visual>
        <collision>
            <geometry>
                <mesh filename="package://kinova_j2s7s300_ign/meshes/collision/wrist_spherical_2.stl"/>
            </geometry>
        </collision>
    </link>

    <link name="j2s7s300_link_7">
        <visual>
            <geometry>
                <mesh filename="package://kinova_j2s7s300_ign/meshes/visual/hand_3finger.dae"/>
            </geometry>
        </visual>
        <visual>
            <geometry>
                <mesh filename="package://kinova_j2s7s300_ign/meshes/visual/ring_small.dae"/>
            </geometry>
        </visual>
        <collision>
            <geometry>
                <mesh filename="package://kinova_j2s7s300_ign/meshes/collision/hand_3finger.stl"/>
            </geometry>
        </collision>
    </link>


    <!-- Arm Joints -->
    <joint name="j2s7s300_joint_1" type="revolute">
        <parent link="j2s7s300_link_base"/>
        <child link="j2s7s300_link_1"/>
        <origin rpy="0 3.14159265359 0" xyz="0 0 0.15675"/>
        <axis xyz="0 0 1"/>
        <limit effort="2000" lower="-6.28318530718" upper="6.28318530718" velocity="1"/>
    </joint>

    <joint name="j2s7s300_joint_2" type="revolute">
        <parent link="j2s7s300_link_1"/>
        <child link="j2s7s300_link_2"/>
        <origin rpy="-1.57079632679 0 3.14159265359" xyz="0 0.0016 -0.11875"/>
        <axis xyz="0 0 1"/>
        <limit effort="2000" lower="0.820304748437" upper="5.46288055874" velocity="1"/>
    </joint>

    <joint name="j2s7s300_joint_3" type="revolute">
        <parent link="j2s7s300_link_2"/>
        <child link="j2s7s300_link_3"/>
        <origin rpy="-1.57079632679 0 0" xyz="0 -0.205 0"/>
        <axis xyz="0 0 1"/>
        <limit effort="2000" lower="-6.28318530718" upper="6.28318530718" velocity="1"/>
    </joint>

    <joint name="j2s7s300_joint_4" type="revolute">
        <parent link="j2s7s300_link_3"/>
        <child link="j2s7s300_link_4"/>
        <origin rpy="1.57079632679 0 3.14159265359" xyz="0 0 -0.205"/>
        <axis xyz="0 0 1"/>
        <limit effort="2000" lower="0.523598775598" upper="5.75958653158" velocity="1"/>
    </joint>

    <joint name="j2s7s300_joint_5" type="revolute">
        <parent link="j2s7s300_link_4"/>
        <child link="j2s7s300_link_5"/>
        <origin rpy="-1.57079632679 0 3.14159265359" xyz="0 0.2073 -0.0114"/>
        <axis xyz="0 0 1"/>
        <limit effort="2000" lower="-6.28318530718" upper="6.28318530718" velocity="1"/>
    </joint>

    <joint name="j2s7s300_joint_6" type="revolute">
        <parent link="j2s7s300_link_5"/>
        <child link="j2s7s300_link_6"/>
        <origin rpy="1.57079632679 0 3.14159265359" xyz="0 0 -0.10375"/>
        <axis xyz="0 0 1"/>
        <limit effort="2000" lower="1.1344640138" upper="5.14872129338" velocity="1"/>
    </joint>

    <joint name="j2s7s300_joint_7" type="revolute">
        <parent link="j2s7s300_link_6"/>
        <child link="j2s7s300_link_7"/>
        <origin rpy="-1.57079632679 0 3.14159265359" xyz="0 0.10375 0"/>
        <axis xyz="0 0 1"/>
        <limit effort="2000" lower="-6.28318530718" upper="6.28318530718" velocity="1"/>
    </joint>


    <!-- Hand Links -->
    <link name="j2s7s300_link_finger_1">
        <visual>
            <geometry>
                <mesh filename="package://kinova_j2s7s300_ign/meshes/visual/finger_proximal.dae"/>
            </geometry>
        </visual>
        <collision>
            <geometry>
                <mesh filename="package://kinova_j2s7s300_ign/meshes/collision/finger_proximal.stl"/>
            </geometry>
        </collision>
    </link>

    <link name="j2s7s300_link_finger_tip_1">
        <visual>
            <geometry>
                <mesh filename="package://kinova_j2s7s300_ign/meshes/visual/finger_distal.dae"/>
            </geometry>
        </visual>
        <collision>
            <geometry>
                <mesh filename="package://kinova_j2s7s300_ign/meshes/collision/finger_distal.stl"/>
            </geometry>
        </collision>
    </link>

    <link name="j2s7s300_link_finger_2">
        <visual>
            <geometry>
                <mesh filename="package://kinova_j2s7s300_ign/meshes/visual/finger_proximal.dae"/>
            </geometry>
        </visual>
        <collision>
            <geometry>
                <mesh filename="package://kinova_j2s7s300_ign/meshes/collision/finger_proximal.stl"/>
            </geometry>
        </collision>
    </link>

    <link name="j2s7s300_link_finger_tip_2">
        <visual>
            <geometry>
                <mesh filename="package://kinova_j2s7s300_ign/meshes/visual/finger_distal.dae"/>
            </geometry>
        </visual>
        <collision>
            <geometry>
                <mesh filename="package://kinova_j2s7s300_ign/meshes/collision/finger_distal.stl"/>
            </geometry>
        </collision>
    </link>

    <link name="j2s7s300_link_finger_3">
        <visual>
            <geometry>
                <mesh filename="package://kinova_j2s7s300_ign/meshes/visual/finger_proximal.dae"/>
            </geometry>
        </visual>
        <collision>
            <geometry>
                <mesh filename="package://kinova_j2s7s300_ign/meshes/collision/finger_proximal.stl"/>
            </geometry>
        </collision>
    </link>

    <link name="j2s7s300_link_finger_tip_3">
        <visual>
            <geometry>
                <mesh filename="package://kinova_j2s7s300_ign/meshes/visual/finger_distal.dae"/>
            </geometry>
        </visual>
        <collision>
            <geometry>
                <mesh filename="package://kinova_j2s7s300_ign/meshes/collision/finger_distal.stl"/>
            </geometry>
        </collision>
    </link>


    <!-- Finger Joints -->
    <joint name="j2s7s300_joint_finger_1" type="revolute">
        <parent link="j2s7s300_link_7"/>
        <child link="j2s7s300_link_finger_1"/>
        <origin rpy="-1.570796327 .649262481663582 1.35961148639407" xyz="0.00279 0.03126 -0.11467"/>
        <axis xyz="0 0 1"/>
        <limit effort="2000" lower="0" upper="2" velocity="1"/>
    </joint>

    <joint name="j2s7s300_joint_finger_tip_1" type="fixed">
        <parent link="j2s7s300_link_finger_1"/>
        <child link="j2s7s300_link_finger_tip_1"/>
        <origin rpy="0 0 0" xyz="0.044 -0.003 0"/>
    </joint>

    <joint name="j2s7s300_joint_finger_2" type="revolute">
        <parent link="j2s7s300_link_7"/>
        <child link="j2s7s300_link_finger_2"/>
        <origin rpy="-1.570796327 .649262481663582 -1.38614049188413" xyz="0.02226 -0.02707 -0.11482"/>
        <axis xyz="0 0 1"/>
        <limit effort="2000" lower="0" upper="2" velocity="1"/>
    </joint>

    <joint name="j2s7s300_joint_finger_tip_2" type="fixed">
        <parent link="j2s7s300_link_finger_2"/>
        <child link="j2s7s300_link_finger_tip_2"/>
        <origin rpy="0 0 0" xyz="0.044 -0.003 0"/>
    </joint>

    <joint name="j2s7s300_joint_finger_3" type="revolute">
        <parent link="j2s7s300_link_7"/>
        <child link="j2s7s300_link_finger_3"/>
        <origin rpy="-1.570796327 .649262481663582 -1.75545216211587" xyz="-0.02226 -0.02707 -0.11482"/>
        <axis xyz="0 0 1"/>
        <limit effort="2000" lower="0" upper="2" velocity="1"/>
    </joint>

    <joint name="j2s7s300_joint_finger_tip_3" type="fixed">
        <parent link="j2s7s300_link_finger_3"/>
        <child link="j2s7s300_link_finger_tip_3"/>
        <origin rpy="0 0 0" xyz="0.044 -0.003 0"/>
    </joint>

    <!-- End-effector -->
    <link name="j2s7s300_end_effector" />
    <joint name="j2s7s300_joint_end_effector" type="fixed">
        <origin rpy="3.14159265359 0 1.57079632679" xyz="0 0 -0.16"/>
        <parent link="j2s7s300_link_7"/>
        <child link="j2s7s300_end_effector"/>
    </joint>

</robot>

